<?xml version="1.0" encoding="utf-8"?>
<mujoco>
    <include file="shared_config.xml"/>
    <worldbody>
        <include file="sawyer_xyz_base.xml"/>
        <include file="bottom_right_lighting.xml"/>
        <body name="door_0" pos="0.30 0.8 0.2">
            <joint name="door_0_joint" pos="-0.1 0 0" axis="0 0 1" type="hinge" limited="true" range="-1.507 0"
                   damping="10" armature="0"/>
            <geom type="box" pos="0 0 0" size="0.1 0.005 0.2" rgba="0 0.5 1 1" contype="1" conaffinity="1"/>
            <geom type="box" pos="0.05 -0.04 0" size="0.05 0.005 0.005" rgba=".75 .75 .75 1" contype="1"
                  conaffinity="1"/>
            <geom type="box" pos="0.095 -0.025 0" size="0.005 0.01975 0.005" rgba=".75 .75 .75 1" contype="1"
                  conaffinity="1"/>
            <site name="door_0_handle" pos="0.05 -0.04 0" size="0.01" rgba="1 0 0 1"/>
        </body>
        <body name="door_1" pos="0 0.8 0.2">
            <joint name="door_1_joint" pos="-0.1 0 0" axis="0 0 1" type="hinge" limited="true" range="-1.507 0"
                   damping="10" armature="0"/>
            <geom type="box" pos="0 0 0" size="0.1 0.005 0.2" rgba="1 0.5 0.5 1" contype="1" conaffinity="1"/>
            <geom type="box" pos="0.05 -0.04 0" size="0.05 0.005 0.005" rgba=".75 .75 .75 1" contype="1"
                  conaffinity="1"/>
            <geom type="box" pos="0.095 -0.025 0" size="0.005 0.01975 0.005" rgba=".75 .75 .75 1" contype="1"
                  conaffinity="1"/>
            <site name="door_1_handle" pos="0.05 -0.04 0" size="0.01" rgba="1 0 0 1"/>
        </body>
    </worldbody>
    <sensor>
        <touch name='rightclaw_sensor' site='rightEndEffector'/>
        <touch name='leftclaw_sensor' site='leftEndEffector'/>
    </sensor>
    <actuator>
        <motor ctrllimited="true" ctrlrange="-1 1" gear="200" joint="r_close"/>
        <motor ctrllimited="true" ctrlrange="-1 1" gear="200" joint="l_close"/>
    </actuator>
</mujoco>
